<?xml version="1.0" encoding="UTF-8"?>
<robot name="Robot">
    <link name="lwr_arm_1_link">
        <inertial>
            <origin rpy="0.00000000 0.00000000 0.00000000" xyz="0.00000000 0.00000000 0.13000000"/>
            <mass value="2.00000000"/>
            <inertia ixx="0.01366667" ixy="0.00000000" ixz="0.00000000" iyy="0.01186667" iyz="0.00000000" izz="0.00300000"/>
        </inertial>
        <visual>
            <origin rpy="0.00000000  0.00000000 -3.14159265" xyz="0.00000000 0.00000000 0.00000000"/>
            <geometry>
                <mesh filename="meshes/visual/arm_segment_a.stl" scale="100.00000000 100.00000000 100.00000000"/>
            </geometry>
            <material name="">
                <color rgba="1.00000000 0.48700000 0.00000000 1.00000000"/>
            </material>
        </visual>
        <collision>
            <origin rpy="0.00000000  0.00000000 -3.14159265" xyz="0.00000000 0.00000000 0.00000000"/>
            <geometry>
                <mesh filename="meshes/collision/arm_segment_a_convex.stl" scale="1.00000000 1.00000000 1.00000000"/>
            </geometry>
        </collision>
    </link>
    <link name="lwr_arm_2_link">
        <inertial>
            <origin rpy="0.00000000 0.00000000 0.00000000" xyz="0.00000000 -0.06000000  0.07000000"/>
            <mass value="2.00000000"/>
            <inertia ixx="0.01366667" ixy="0.00000000" ixz="0.00000000" iyy="0.01186667" iyz="0.00000000" izz="0.00300000"/>
        </inertial>
        <visual>
            <origin rpy="-3.14159265  0.00000000 -3.14159265" xyz="0.00000000 0.00000000 0.20000000"/>
            <geometry>
                <mesh filename="meshes/visual/arm_segment_b.stl" scale="100.00000000 100.00000000 100.00000000"/>
            </geometry>
            <material name="">
                <color rgba="1.00000000 0.48700000 0.00000000 1.00000000"/>
            </material>
        </visual>
        <collision>
            <origin rpy="-3.14159265  0.00000000 -3.14159265" xyz="0.00000000 0.00000000 0.20000000"/>
            <geometry>
                <mesh filename="meshes/collision/arm_segment_b_convex.stl" scale="1.00000000 1.00000000 1.00000000"/>
            </geometry>
        </collision>
    </link>
    <link name="lwr_arm_3_link">
        <inertial>
            <origin rpy="0.00000000 0.00000000 0.00000000" xyz="0.00000000 -0.06000000  0.13000000"/>
            <mass value="2.00000000"/>
            <inertia ixx="0.01366667" ixy="0.00000000" ixz="0.00000000" iyy="0.01186667" iyz="0.00000000" izz="0.00300000"/>
        </inertial>
        <visual>
            <origin rpy="0.00000000 0.00000000 0.00000000" xyz="0.00000000 0.00000000 0.00000000"/>
            <geometry>
                <mesh filename="meshes/visual/arm_segment_a.stl" scale="100.00000000 100.00000000 100.00000000"/>
            </geometry>
            <material name="">
                <color rgba="1.00000000 0.48700000 0.00000000 1.00000000"/>
            </material>
        </visual>
        <collision>
            <origin rpy="0.00000000 0.00000000 0.00000000" xyz="0.00000000 0.00000000 0.00000000"/>
            <geometry>
                <mesh filename="meshes/collision/arm_segment_a_convex.stl" scale="1.00000000 1.00000000 1.00000000"/>
            </geometry>
        </collision>
    </link>
    <link name="lwr_arm_4_link">
        <inertial>
            <origin rpy="0.00000000 0.00000000 0.00000000" xyz="0.00000000 0.06000000 0.07000000"/>
            <mass value="2.00000000"/>
            <inertia ixx="0.01366667" ixy="0.00000000" ixz="0.00000000" iyy="0.01186667" iyz="0.00000000" izz="0.00300000"/>
        </inertial>
        <visual>
            <origin rpy="-3.14159265 -0.00000000  0.00000000" xyz="0.00000000 0.00000000 0.20000000"/>
            <geometry>
                <mesh filename="meshes/visual/arm_segment_b.stl" scale="100.00000000 100.00000000 100.00000000"/>
            </geometry>
            <material name="">
                <color rgba="1.00000000 0.48700000 0.00000000 1.00000000"/>
            </material>
        </visual>
        <collision>
            <origin rpy="-3.14159265 -0.00000000  0.00000000" xyz="0.00000000 0.00000000 0.20000000"/>
            <geometry>
                <mesh filename="meshes/collision/arm_segment_b_convex.stl" scale="1.00000000 1.00000000 1.00000000"/>
            </geometry>
        </collision>
    </link>
    <link name="lwr_arm_5_link">
        <inertial>
            <origin rpy="0.00000000 0.00000000 0.00000000" xyz="0.00000000 0.00000000 0.12400000"/>
            <mass value="2.00000000"/>
            <inertia ixx="0.01265067" ixy="0.00000000" ixz="0.00000000" iyy="0.01085067" iyz="0.00000000" izz="0.00300000"/>
        </inertial>
        <visual>
            <origin rpy="0.00000000  0.00000000 -3.14159265" xyz="0.00000000 0.00000000 0.00000000"/>
            <geometry>
                <mesh filename="meshes/visual/arm_segment_last.stl" scale="100.00000000 100.00000000 100.00000000"/>
            </geometry>
            <material name="">
                <color rgba="1.00000000 0.48700000 0.00000000 1.00000000"/>
            </material>
        </visual>
        <collision>
            <origin rpy="0.00000000  0.00000000 -3.14159265" xyz="0.00000000 0.00000000 0.00000000"/>
            <geometry>
                <mesh filename="meshes/collision/arm_segment_last_convex.stl" scale="1.00000000 1.00000000 1.00000000"/>
            </geometry>
        </collision>
    </link>
    <link name="lwr_arm_6_link">
        <inertial>
            <origin rpy="0.00000000 0.00000000 0.00000000" xyz="0.00000000 0.00000000 0.00000000"/>
            <mass value="1.00000000"/>
            <inertia ixx="0.00260417" ixy="0.00000000" ixz="0.00000000" iyy="0.00260417" iyz="0.00000000" izz="0.00260417"/>
        </inertial>
        <visual>
            <origin rpy="0.00000000  0.00000000 -3.14159265" xyz="0.00000000 0.00000000 0.00000000"/>
            <geometry>
                <mesh filename="meshes/visual/arm_wrist.stl" scale="100.00000000 100.00000000 100.00000000"/>
            </geometry>
            <material name="">
                <color rgba="0.70000000 0.70000000 0.70000000 1.00000000"/>
            </material>
        </visual>
        <collision>
            <origin rpy="0.00000000  0.00000000 -3.14159265" xyz="0.00000000 0.00000000 0.00000000"/>
            <geometry>
                <mesh filename="meshes/collision/arm_wrist_convex.stl" scale="1.00000000 1.00000000 1.00000000"/>
            </geometry>
        </collision>
    </link>
    <link name="lwr_arm_7_link">
        <inertial>
            <origin rpy="0.00000000 0.00000000 0.00000000" xyz="0.00000000 0.00000000 0.00000000"/>
            <mass value="0.20000000"/>
            <inertia ixx="0.00006667" ixy="0.00000000" ixz="0.00000000" iyy="0.00006667" iyz="0.00000000" izz="0.00012000"/>
        </inertial>
        <visual>
            <origin rpy="0.00000000 0.00000000 0.00000000" xyz="0.00000000 0.00000000 0.00000000"/>
            <geometry>
                <mesh filename="meshes/visual/arm_flanche.stl" scale="100.00000000 100.00000000 100.00000000"/>
            </geometry>
            <material name="">
                <color rgba="0.70000000 0.70000000 0.70000000 1.00000000"/>
            </material>
        </visual>
        <collision>
            <origin rpy="0.00000000 0.00000000 0.00000000" xyz="0.00000000 0.00000000 0.00000000"/>
            <geometry>
                <mesh filename="meshes/collision/arm_flanche.stl" scale="100.00000000 100.00000000 100.00000000"/>
            </geometry>
        </collision>
    </link>
    <link name="lwr_arm_base_link">
        <inertial>
            <origin rpy="0.00000000 0.00000000 0.00000000" xyz="0.00000000 0.00000000 0.05500000"/>
            <mass value="1.20000000"/>
            <inertia ixx="0.00229000" ixy="0.00000000" ixz="0.00000000" iyy="0.00216000" iyz="0.00000000" izz="0.00229000"/>
        </inertial>
        <visual>
            <origin rpy="0.00000000 0.00000000 0.00000000" xyz="0.00000000 0.00000000 0.00000000"/>
            <geometry>
                <mesh filename="meshes/visual/arm_base.stl" scale="100.00000000 100.00000000 100.00000000"/>
            </geometry>
            <material name="">
                <color rgba="1.00000000 0.48700000 0.00000000 1.00000000"/>
            </material>
        </visual>
        <collision>
            <origin rpy="0.00000000 0.00000000 0.00000000" xyz="0.00000000 0.00000000 0.01000000"/>
            <geometry>
                <mesh filename="meshes/collision/arm_base_convex.stl" scale="0.90000000 0.90000000 0.90000000"/>
            </geometry>
        </collision>
    </link>
    <link name="world">
        <inertial>
            <mass value="0"/>
            <inertia ixx="0" ixy="0" ixz="0" iyy="0" iyz="0" izz="0"/>
        </inertial>
    </link>
    <joint name="arm_world_joint" type="fixed">
        <parent link="world"/>
        <child link="lwr_arm_base_link"/>
        <origin rpy="0.00000000 0.00000000 0.00000000" xyz="0.00000000 0.00000000 0.01000000"/>
        <axis xyz="100"/>
    </joint>
    <joint name="lwr_arm_0_joint" type="revolute">
        <parent link="lwr_arm_base_link"/>
        <child link="lwr_arm_1_link"/>
        <origin rpy="0.00000000 0.00000000 0.00000000" xyz="0.00000000 0.00000000 0.11000000"/>
        <axis xyz="0.00000000 0.00000000 1.00000000"/>
        <limit lower="-2.96705973" upper="2.96705973" effort="0" velocity="0"/>
    </joint>
    <joint name="lwr_arm_1_joint" type="revolute">
        <parent link="lwr_arm_1_link"/>
        <child link="lwr_arm_2_link"/>
        <origin rpy="0.00000000 0.00000000 0.00000000" xyz="0.00000000 0.00000000 0.20000000"/>
        <axis xyz="0.00000000 -1.00000000  0.00000000"/>
        <limit lower="-2.09439510" upper="2.09439510" effort="0" velocity="0"/>
    </joint>
    <joint name="lwr_arm_2_joint" type="revolute">
        <parent link="lwr_arm_2_link"/>
        <child link="lwr_arm_3_link"/>
        <origin rpy="0.00000000 0.00000000 0.00000000" xyz="0.00000000 0.00000000 0.20000000"/>
        <axis xyz="0.00000000 0.00000000 1.00000000"/>
        <limit lower="-2.96705973" upper="2.96705973" effort="0" velocity="0"/>
    </joint>
    <joint name="lwr_arm_3_joint" type="revolute">
        <parent link="lwr_arm_3_link"/>
        <child link="lwr_arm_4_link"/>
        <origin rpy="0.00000000 0.00000000 0.00000000" xyz="0.00000000 0.00000000 0.20000000"/>
        <axis xyz="0.00000000 1.00000000 0.00000000"/>
        <limit lower="-2.09439510" upper="2.09439510" effort="0" velocity="0"/>
    </joint>
    <joint name="lwr_arm_4_joint" type="revolute">
        <parent link="lwr_arm_4_link"/>
        <child link="lwr_arm_5_link"/>
        <origin rpy="0.00000000 0.00000000 0.00000000" xyz="0.00000000 0.00000000 0.20000000"/>
        <axis xyz="0.00000000 0.00000000 1.00000000"/>
        <limit lower="-2.96705973" upper="2.96705973" effort="0" velocity="0"/>
    </joint>
    <joint name="lwr_arm_5_joint" type="revolute">
        <parent link="lwr_arm_5_link"/>
        <child link="lwr_arm_6_link"/>
        <origin rpy="0.00000000 0.00000000 0.00000000" xyz="0.00000000 0.00000000 0.19000000"/>
        <axis xyz="0.00000000 -1.00000000  0.00000000"/>
        <limit lower="-2.09439510" upper="2.09439510" effort="0" velocity="0"/>
    </joint>
    <joint name="lwr_arm_6_joint" type="revolute">
        <parent link="lwr_arm_6_link"/>
        <child link="lwr_arm_7_link"/>
        <origin rpy="0.00000000 0.00000000 0.00000000" xyz="0.00000000 0.00000000 0.00000000"/>
        <axis xyz="0.00000000 0.00000000 1.00000000"/>
        <limit lower="-2.96705973" upper="2.96705973" effort="0" velocity="0"/>
    </joint>
</robot>
