<?xml version="1.0" ?>
<!-- =================================================================================== -->
<!-- |    This document was autogenerated by xacro from ./single_lwr_robot.urdf.xacro  | -->
<!-- |    EDITING THIS FILE BY HAND IS NOT RECOMMENDED                                 | -->
<!-- =================================================================================== -->
<robot xmlns:xacro="http://www.ros.org/wiki/xacro" name="single_lwr_robot">
  <!-- Include all models -->
  <material name="Kuka/DarkGrey">
    <color rgba="0.3 0.3 0.3 1.0"/>
  </material>
  <material name="Kuka/LightGrey">
    <color rgba="0.8 0.8 0.8 1.0"/>
  </material>
  <material name="Kuka/Red">
    <color rgba="0.3 0.3 0.3 1.0"/>
  </material>
  <material name="Kuka/Black">
    <color rgba="0 0 0 1.0"/>
  </material>
  <material name="Kuka/Orange">
    <color rgba="1.0 0.487 0 1.0"/>
  </material>
  <material name="Kuka/Silver">
    <color rgba="1.0 1.0 1.0 1.0"/>
  </material>
  <material name="Kuka/Grey">
    <color rgba="0.7 0.7 0.7 1.0"/>
  </material>
  <material name="Kuka/Blue">
    <color rgba="0.0 0.0 0.8 1.0"/>
  </material>
  <!-- and assemble your robot -->
  <link name="box">
    <inertial>
      <mass value="5.0"/>
      <origin rpy="0 0 0" xyz="0 0 0"/>
      <inertia ixx="0.01" iyy="0.01" izz="0.01" ixy="0" iyz="0" ixz="0"/>
    </inertial>
    <visual>
      <origin xyz="0 0 0.50" rpy="0 0 0"/>
      <geometry>
        <box size="1.0 1.0 1.0"/>
      </geometry>
    </visual>
    <collision>
      <origin xyz="0 0 0.50" rpy="0 0 0"/>
      <geometry>
        <box size="1.0 1.0 1.0"/>
      </geometry>
    </collision>
  </link>
  <gazebo reference="box">
    <static>true</static>
  </gazebo>
  <!-- using the models -->
  <joint name="box_lwr_base_joint" type="fixed">
    <origin xyz="0 0 1" rpy="0 0 0"/>
    <origin xyz="0 0 0" rpy="0 0 0"/>
    <parent link="box"/>
    <child link="lwr_base_link"/>
  </joint>
  <link name="lwr_base_link">
    <inertial>
      <mass value="2.0"/>
      <origin xyz="0 0 0.055"/>
      <inertia ixx="0.003816666666666666" iyy="0.0036" izz="0.003816666666666666" ixy="0" iyz="0" ixz="0"/>
    </inertial>
    <visual>
      <origin xyz="0 0 0" rpy="0 0 3.141592653589793"/>
      <geometry>
        <mesh filename="package://lwr_description/meshes/lwr4plus/visual/base.STL"/>
      </geometry>
      <material name="Kuka/Orange"/>
    </visual>
    <collision>
      <origin xyz="0 0 0.055" rpy="0 0 3.141592653589793"/>
      <geometry>
        <cylinder radius="0.07" length="0.11"/>
      </geometry>
    </collision>
  </link>
  <joint name="lwr_a1_joint" type="revolute">
    <origin xyz="0 0 0.11" rpy="0 0 0"/>
    <axis xyz="0 0 1"/>
    <limit lower="-2.9670597283903604" upper="2.9670597283903604" effort="176" velocity="1.9198621771937625"/>
    <dynamics friction="10.0" damping="1.0"/>
    <parent link="lwr_base_link"/>
    <child link="lwr_1_link"/>
  </joint>
  <joint name="lwr_a1_joint_stiffness" type="revolute">
    <axis xyz="0 0 1"/>
    <limit lower="0" upper="5000" effort="0" velocity="20000"/>
    <safety_controller soft_lower_limit="0" soft_upper_limit="5000" k_position="30" k_velocity="30"/>
    <parent link="lwr_base_link"/>
    <child link="lwr_1_link_dummy"/>
  </joint>
  <link name="lwr_1_link_dummy"/>
  <link name="lwr_1_link">
    <inertial>
      <mass value="2.35"/>
      <origin rpy="0 0 0" xyz="0 -0.06 0.130"/>
      <inertia ixx="0.016058333333333334" iyy="0.003525" izz="0.013943333333333335" ixy="0" iyz="0" ixz="0"/>
    </inertial>
    <visual>
      <origin xyz="0 0 -0.008" rpy="0 0 3.141592653589793"/>
      <geometry>
        <mesh filename="package://lwr_description/meshes/lwr4plus/visual/link_1.STL"/>
      </geometry>
      <material name="Kuka/Orange"/>
    </visual>
    <collision>
      <origin xyz="0 0 0.0" rpy="0 0 0"/>
      <geometry>
        <sphere radius="0.07"/>
      </geometry>
    </collision>
    <collision>
      <origin xyz="0 0.06 0.2" rpy="0 0 0"/>
      <geometry>
        <sphere radius="0.07"/>
      </geometry>
    </collision>
    <collision>
      <origin xyz="0 0.03 0.1" rpy="-0.291 0 0"/>
      <geometry>
        <cylinder radius="0.07" length="0.208"/>
      </geometry>
    </collision>
  </link>
  <joint name="lwr_a2_joint" type="revolute">
    <origin xyz="0 0 0.2005" rpy="0 0 0"/>
    <axis xyz="0 -1 0"/>
    <limit lower="-2.0943951023931953" upper="2.0943951023931953" effort="176" velocity="1.9198621771937625"/>
    <dynamics friction="10.0" damping="1.0"/>
    <parent link="lwr_1_link"/>
    <child link="lwr_2_link"/>
  </joint>
  <joint name="lwr_a2_joint_stiffness" type="revolute">
    <axis xyz="0 0 1"/>
    <limit lower="0" upper="5000" effort="0" velocity="20000"/>
    <safety_controller soft_lower_limit="0" soft_upper_limit="5000" k_position="30" k_velocity="30"/>
    <parent link="lwr_1_link"/>
    <child link="lwr_2_link_dummy"/>
  </joint>
  <link name="lwr_2_link_dummy"/>
  <link name="lwr_2_link">
    <inertial>
      <mass value="2.35"/>
      <origin rpy="0 0 0" xyz="0 0.06 0.07"/>
      <inertia ixx="0.016058333333333334" iyy="0.003525" izz="0.013943333333333335" ixy="0" iyz="0" ixz="0"/>
    </inertial>
    <visual>
      <origin xyz="0 0 0.0" rpy="0 0 3.141592653589793"/>
      <geometry>
        <mesh filename="package://lwr_description/meshes/lwr4plus/visual/link_2.STL"/>
      </geometry>
      <material name="Kuka/Orange"/>
    </visual>
    <collision>
      <origin xyz="0 0 0.2" rpy="0 0 0"/>
      <geometry>
        <sphere radius="0.07"/>
      </geometry>
    </collision>
    <collision>
      <origin xyz="0 -0.06 0.0" rpy="0 0 0"/>
      <geometry>
        <sphere radius="0.07"/>
      </geometry>
    </collision>
    <collision>
      <origin xyz="0 -0.03 0.1" rpy="-0.291 0 0"/>
      <geometry>
        <cylinder radius="0.07" length="0.208"/>
      </geometry>
    </collision>
  </link>
  <joint name="lwr_e1_joint" type="revolute">
    <origin xyz="0 0 0.20" rpy="0 0 0"/>
    <axis xyz="0 0 1"/>
    <limit lower="-2.9670597283903604" upper="2.9670597283903604" effort="100" velocity="2.234021442552742"/>
    <dynamics friction="10.0" damping="1.0"/>
    <parent link="lwr_2_link"/>
    <child link="lwr_3_link"/>
  </joint>
  <joint name="lwr_e1_joint_stiffness" type="revolute">
    <axis xyz="0 0 1"/>
    <limit lower="0" upper="5000" effort="0" velocity="20000"/>
    <safety_controller soft_lower_limit="0" soft_upper_limit="5000" k_position="30" k_velocity="30"/>
    <parent link="lwr_2_link"/>
    <child link="lwr_3_link_dummy"/>
  </joint>
  <link name="lwr_3_link_dummy"/>
  <link name="lwr_3_link">
    <inertial>
      <mass value="2.35"/>
      <origin rpy="0 0 0" xyz="0 0.06 0.130"/>
      <inertia ixx="0.016058333333333334" iyy="0.003525" izz="0.013943333333333335" ixy="0" iyz="0" ixz="0"/>
    </inertial>
    <visual>
      <origin xyz="0 0 -0.008" rpy="0 0 3.141592653589793"/>
      <geometry>
        <mesh filename="package://lwr_description/meshes/lwr4plus/visual/link_3.STL"/>
      </geometry>
      <material name="Kuka/Orange"/>
    </visual>
    <collision>
      <origin xyz="0 0 0.0" rpy="0 0 0"/>
      <geometry>
        <sphere radius="0.07"/>
      </geometry>
    </collision>
    <collision>
      <origin xyz="0 -0.06 0.2" rpy="0 0 0"/>
      <geometry>
        <sphere radius="0.07"/>
      </geometry>
    </collision>
    <collision>
      <origin xyz="0 -0.03 0.1" rpy="0.291 0 0"/>
      <geometry>
        <cylinder radius="0.07" length="0.208"/>
      </geometry>
    </collision>
  </link>
  <joint name="lwr_a3_joint" type="revolute">
    <origin xyz="0 0 0.20" rpy="0 0 0"/>
    <axis xyz="0 1 0"/>
    <limit lower="-2.0943951023931953" upper="2.0943951023931953" effort="100" velocity="2.234021442552742"/>
    <dynamics friction="10.0" damping="1.0"/>
    <parent link="lwr_3_link"/>
    <child link="lwr_4_link"/>
  </joint>
  <joint name="lwr_a3_joint_stiffness" type="revolute">
    <axis xyz="0 0 1"/>
    <limit lower="0" upper="5000" effort="0" velocity="20000"/>
    <safety_controller soft_lower_limit="0" soft_upper_limit="5000" k_position="30" k_velocity="30"/>
    <parent link="lwr_3_link"/>
    <child link="lwr_4_link_dummy"/>
  </joint>
  <link name="lwr_4_link_dummy"/>
  <link name="lwr_4_link">
    <inertial>
      <mass value="2.35"/>
      <origin rpy="0 0 0" xyz="0 -0.06 0.07"/>
      <inertia ixx="0.016058333333333334" iyy="0.003525" izz="0.013943333333333335" ixy="0" iyz="0" ixz="0"/>
    </inertial>
    <visual>
      <origin xyz="0 0 0.0" rpy="0 0 3.141592653589793"/>
      <geometry>
        <mesh filename="package://lwr_description/meshes/lwr4plus/visual/link_4.STL"/>
      </geometry>
      <material name="Kuka/Orange"/>
    </visual>
    <collision>
      <origin xyz="0 0 0.2" rpy="0 0 0"/>
      <geometry>
        <sphere radius="0.07"/>
      </geometry>
    </collision>
    <collision>
      <origin xyz="0 0.06 0.0" rpy="0 0 0"/>
      <geometry>
        <sphere radius="0.07"/>
      </geometry>
    </collision>
    <collision>
      <origin xyz="0 0.03 0.1" rpy="0.291 0 0"/>
      <geometry>
        <cylinder radius="0.07" length="0.208"/>
      </geometry>
    </collision>
  </link>
  <joint name="lwr_a4_joint" type="revolute">
    <origin xyz="0 0 0.20" rpy="0 0 0"/>
    <axis xyz="0 0 1"/>
    <limit lower="-2.9670597283903604" upper="2.9670597283903604" effort="100" velocity="3.560471674068432"/>
    <dynamics friction="10.0" damping="1.0"/>
    <parent link="lwr_4_link"/>
    <child link="lwr_5_link"/>
  </joint>
  <joint name="lwr_a4_joint_stiffness" type="revolute">
    <axis xyz="0 0 1"/>
    <limit lower="0" upper="5000" effort="0" velocity="20000"/>
    <safety_controller soft_lower_limit="0" soft_upper_limit="5000" k_position="30" k_velocity="30"/>
    <parent link="lwr_4_link"/>
    <child link="lwr_5_link_dummy"/>
  </joint>
  <link name="lwr_5_link_dummy"/>
  <link name="lwr_5_link">
    <inertial>
      <mass value="2.35"/>
      <origin rpy="0 0 0" xyz="0 0 0.124"/>
      <inertia ixx="0.014864533333333334" iyy="0.003525" izz="0.012749533333333334" ixy="0" iyz="0" ixz="0"/>
    </inertial>
    <visual>
      <origin xyz="0 0 -0.008" rpy="0 0 3.141592653589793"/>
      <geometry name="lwr_5_geom">
        <mesh filename="package://lwr_description/meshes/lwr4plus/visual/link_5.STL"/>
      </geometry>
      <material name="Kuka/Orange"/>
    </visual>
    <collision>
      <origin xyz="0 0 0.0" rpy="0 0 0"/>
      <geometry>
        <sphere radius="0.07"/>
      </geometry>
    </collision>
    <collision>
      <origin xyz="0 0.04 0.19" rpy="0 0 0"/>
      <geometry>
        <sphere radius="0.07"/>
      </geometry>
    </collision>
    <collision>
      <origin xyz="0 0.02 0.095" rpy="-0.207 0 0"/>
      <geometry>
        <cylinder radius="0.07" length="0.198"/>
      </geometry>
    </collision>
  </link>
  <joint name="lwr_a5_joint" type="revolute">
    <origin xyz="0 0 0.19" rpy="0 0 0"/>
    <axis xyz="0 -1 0"/>
    <limit lower="-2.0943951023931953" upper="2.0943951023931953" effort="38" velocity="3.211405823669566"/>
    <dynamics friction="10.0" damping="1.0"/>
    <parent link="lwr_5_link"/>
    <child link="lwr_6_link"/>
  </joint>
  <joint name="lwr_a5_joint_stiffness" type="revolute">
    <axis xyz="0 0 1"/>
    <limit lower="0" upper="5000" effort="0" velocity="20000"/>
    <safety_controller soft_lower_limit="0" soft_upper_limit="5000" k_position="30" k_velocity="30"/>
    <parent link="lwr_5_link"/>
    <child link="lwr_6_link_dummy"/>
  </joint>
  <link name="lwr_6_link_dummy"/>
  <link name="lwr_6_link">
    <inertial>
      <mass value="1.1"/>
      <origin rpy="0 0 0" xyz="0 0 0.0625"/>
      <inertia ixx="0.0028645833333333336" iyy="0.0028645833333333336" izz="0.0028645833333333336" ixy="0" iyz="0" ixz="0"/>
    </inertial>
    <visual>
      <origin xyz="0 0 0" rpy="0 0 3.141592653589793"/>
      <geometry>
        <mesh filename="package://lwr_description/meshes/lwr4plus/visual/link_6.STL"/>
      </geometry>
      <material name="Kuka/Grey"/>
    </visual>
    <collision>
      <origin xyz="0 -0.01 0" rpy="0 0 3.141592653589793"/>
      <geometry>
        <sphere radius="0.08"/>
      </geometry>
    </collision>
  </link>
  <joint name="lwr_a6_joint" type="revolute">
    <origin xyz="0 0 0.078" rpy="0 0 0"/>
    <axis xyz="0 0 1"/>
    <limit lower="-2.9670597283903604" upper="2.9670597283903604" effort="38" velocity="3.211405823669566"/>
    <dynamics friction="10.0" damping="1.0"/>
    <parent link="lwr_6_link"/>
    <child link="lwr_7_link"/>
  </joint>
  <joint name="lwr_a6_joint_stiffness" type="revolute">
    <axis xyz="0 0 1"/>
    <limit lower="0" upper="5000" effort="0" velocity="20000"/>
    <safety_controller soft_lower_limit="0" soft_upper_limit="5000" k_position="30" k_velocity="30"/>
    <parent link="lwr_6_link"/>
    <child link="lwr_7_link_dummy"/>
  </joint>
  <link name="lwr_7_link_dummy"/>
  <link name="lwr_7_link">
    <inertial>
      <mass value="0.25"/>
      <origin xyz="0 0 0"/>
      <inertia ixx="0.00041666666666666675" iyy="0.00041666666666666675" izz="0.00041666666666666675" ixy="0" iyz="0" ixz="0"/>
    </inertial>
    <visual>
      <origin xyz="0 0 0" rpy="0 0 3.141592653589793"/>
      <geometry>
        <mesh filename="package://lwr_description/meshes/lwr4plus/visual/link_7.STL"/>
      </geometry>
      <material name="Kuka/DarkGrey"/>
    </visual>
    <collision>
      <origin xyz="0 0 0" rpy="0 0 3.141592653589793"/>
      <geometry>
        <cylinder radius="0.04" length="0.05"/>
      </geometry>
    </collision>
  </link>
  <gazebo>
    <plugin name="lwr_lwr_hw_sim" filename="liblwr_hw_gazebo_plugin.so">
      <robotNamespace>lwr</robotNamespace>
    </plugin>
  </gazebo>
  <gazebo reference="lwr_base_link">
    <gravity>true</gravity>
    <material>Gazebo/Orange</material>
  </gazebo>
  <gazebo reference="lwr_1_link">
    <gravity>true</gravity>
    <material>Gazebo/Orange</material>
  </gazebo>
  <gazebo reference="lwr_2_link">
    <gravity>true</gravity>
    <material>Gazebo/Orange</material>
  </gazebo>
  <gazebo reference="lwr_3_link">
    <gravity>true</gravity>
    <material>Gazebo/Orange</material>
  </gazebo>
  <gazebo reference="lwr_4_link">
    <gravity>true</gravity>
    <material>Gazebo/Orange</material>
  </gazebo>
  <gazebo reference="lwr_5_link">
    <gravity>true</gravity>
    <material>Gazebo/Orange</material>
  </gazebo>
  <gazebo reference="lwr_6_link">
    <gravity>true</gravity>
    <material>Gazebo/Orange</material>
  </gazebo>
  <gazebo reference="lwr_7_link">
    <gravity>true</gravity>
    <material>Gazebo/Grey</material>
  </gazebo>
  <transmission name="lwr_a1_trans">
    <type>transmission_interface/SimpleTransmission</type>
    <joint name="lwr_a1_joint">
      <hardwareInterface>PositionJointInterface</hardwareInterface>
      <hardwareInterface>EffortJointInterface</hardwareInterface>
    </joint>
    <actuator name="lwr_a1_motor">
      <mechanicalReduction>1</mechanicalReduction>
    </actuator>
  </transmission>
  <transmission name="lwr_a2_trans">
    <type>transmission_interface/SimpleTransmission</type>
    <joint name="lwr_a2_joint">
      <hardwareInterface>PositionJointInterface</hardwareInterface>
      <hardwareInterface>EffortJointInterface</hardwareInterface>
    </joint>
    <actuator name="lwr_a2_motor">
      <mechanicalReduction>1</mechanicalReduction>
    </actuator>
  </transmission>
  <transmission name="lwr_e1_trans">
    <type>transmission_interface/SimpleTransmission</type>
    <joint name="lwr_e1_joint">
      <hardwareInterface>PositionJointInterface</hardwareInterface>
      <hardwareInterface>EffortJointInterface</hardwareInterface>
    </joint>
    <actuator name="lwr_e1_motor">
      <mechanicalReduction>1</mechanicalReduction>
    </actuator>
  </transmission>
  <transmission name="lwr_a3_trans">
    <type>transmission_interface/SimpleTransmission</type>
    <joint name="lwr_a3_joint">
      <hardwareInterface>PositionJointInterface</hardwareInterface>
      <hardwareInterface>EffortJointInterface</hardwareInterface>
    </joint>
    <actuator name="lwr_a3_motor">
      <mechanicalReduction>1</mechanicalReduction>
    </actuator>
  </transmission>
  <transmission name="lwr_a4_trans">
    <type>transmission_interface/SimpleTransmission</type>
    <joint name="lwr_a4_joint">
      <hardwareInterface>PositionJointInterface</hardwareInterface>
      <hardwareInterface>EffortJointInterface</hardwareInterface>
    </joint>
    <actuator name="lwr_a4_motor">
      <mechanicalReduction>1</mechanicalReduction>
    </actuator>
  </transmission>
  <transmission name="lwr_a5_trans">
    <type>transmission_interface/SimpleTransmission</type>
    <joint name="lwr_a5_joint">
      <hardwareInterface>PositionJointInterface</hardwareInterface>
      <hardwareInterface>EffortJointInterface</hardwareInterface>
    </joint>
    <actuator name="lwr_a5_motor">
      <mechanicalReduction>1</mechanicalReduction>
    </actuator>
  </transmission>
  <transmission name="lwr_a6_trans">
    <type>transmission_interface/SimpleTransmission</type>
    <joint name="lwr_a6_joint">
      <hardwareInterface>PositionJointInterface</hardwareInterface>
      <hardwareInterface>EffortJointInterface</hardwareInterface>
    </joint>
    <actuator name="lwr_a6_motor">
      <mechanicalReduction>1</mechanicalReduction>
    </actuator>
  </transmission>
</robot>
